#VRML_SIM R2022a utf8
WorldInfo {
}
Viewpoint {
  orientation 0.3670946767487973 -0.657355242876972 -0.6581227719543318 4.957109561525127
  position -3.7945722586712045 -8.980582355143975 10.018645971391384
}
TexturedBackground {
  texture "mars"
}
TexturedBackgroundLight {
  luminosity 2
}
UnevenTerrain {
  translation 0 0 -4.44
  appearance SandyGround {
    colorOverride 0.55 0.55 0.4
    textureTransform TextureTransform {
      scale 50 50
    }
  }
}
Solid {
  translation 4.48735 -5.26786 -0.795355
  rotation 0.3894717886604402 0.6072618419483917 0.6924917191931498 2.3758474234853373
  children [
    DEF box Shape {
      appearance DryMud {
      }
      geometry Box {
        size 1 1.5 2
      }
    }
  ]
  name "solid(2)"
  boundingObject USE box
  physics DEF phy1 Physics {
    mass 1
  }
}
Solid {
  translation 1.0157931288032793 -0.74682561001838 -0.5074259999605989
  rotation 0.9993526972514696 -0.03187465456711724 0.0166791154573519 1.6467302959761718
  children [
    DEF box Shape {
      appearance DryMud {
      }
      geometry Box {
        size 0.8 1.7 0.9
      }
    }
  ]
  name "solid(4)"
  boundingObject USE box
  physics USE phy1
}
Solid {
  translation 1.158526586800406 -3.2870964993927454 -1.1240117817078419
  rotation 0.8812696216870441 -0.3395745957706464 -0.3287140821424849 1.8251205645406967
  children [
    DEF box Shape {
      appearance DryMud {
      }
      geometry Box {
        size 1.5 0.9 0.9
      }
    }
  ]
  name "solid(1)"
  boundingObject USE box
  physics DEF phy1 Physics {
    mass 1
  }
}
Robot {
  translation 3.8199089347414934 -1.5878406713515445 -0.9626367926737905
  rotation 0.21548897364393563 -0.1460881244807486 -0.9655168367892817 0.42735760959122665
  children [
    DEF body Shape {
      appearance HammeredCopper {
      }
      geometry Box {
        size 0.7 0.5 0.2
      }
    }
    DistanceSensor {
      translation -0.35 -0.14 0
      rotation 0 0 1 -2.5
      children [
        DEF ds Shape {
          appearance ReflectiveSurface {
          }
          geometry Box {
            size 0.05 0.05 0.05
          }
        }
      ]
      name "ds1"
      boundingObject USE ds
      physics Physics {
        mass 1
      }
      translationStep 0.11
      lookupTable [
        0 0 0
        1 1000 0
      ]
      aperture 1.5715
    }
    DistanceSensor {
      translation -0.35 0.15 0
      rotation 0 0 1 2.6763956132800115
      children [
        DEF ds2 Shape {
          appearance ReflectiveSurface {
          }
          geometry Box {
            size 0.05 0.05 0.05
          }
        }
      ]
      name "ds2"
      boundingObject USE ds2
      physics Physics {
        mass 1
      }
      lookupTable [
        0 0 0
        1 1000 0
      ]
    }
    Solid {
      translation 0.03 0 0.19
      children [
        DEF panel Shape {
          appearance SolarCell {
          }
          geometry Box {
            size 0.6 0.5 0.01
          }
        }
        Solid {
          translation 0.25 -0.19 -0.05
          children [
            Shape {
              appearance Copper {
              }
              geometry Cylinder {
                height 0.1
                radius 0.02
              }
            }
          ]
          name "solar_panel_support1"
        }
        Solid {
          translation 0.25 0.19 -0.05
          children [
            Shape {
              appearance Copper {
              }
              geometry Cylinder {
                height 0.1
                radius 0.02
              }
            }
          ]
          name "solar_panel_support2"
        }
        Solid {
          translation -0.25 0.19 -0.05
          children [
            Shape {
              appearance Copper {
              }
              geometry Cylinder {
                height 0.1
                radius 0.02
              }
            }
          ]
          name "solar_panel_support3"
        }
        Solid {
          translation -0.25 -0.19 -0.05
          children [
            Shape {
              appearance Copper {
              }
              geometry Cylinder {
                height 0.1
                radius 0.02
              }
            }
          ]
          name "solar_panel_support4"
        }
      ]
      name "solar_panel"
    }
    Solid {
      translation -0.18 -0.24 0
      children [
        Solid {
          translation -0.00017766252744422228 -0.017340268664742475 0.05993637531167906
          rotation -0.9999999929357695 8.124469320562993e-05 -8.676267159571073e-05 1.5708626067521982
          children [
            DEF cylinder1 Shape {
              appearance DamascusSteel {
              }
              geometry Cylinder {
                height 0.09
                radius 0.02
              }
            }
            Solid {
              translation 0 0 -0.05
              children [
                DEF sphere1 Shape {
                  appearance BrushedSteel {
                  }
                  geometry Sphere {
                    radius 0.02
                  }
                }
                Solid {
                  translation 0 0.1 1.79608e-07
                  rotation -1 0 0 -1.5707953071795862
                  children [
                    DEF cylinder2 Shape {
                      appearance BrushedSteel {
                      }
                      geometry Cylinder {
                        height 0.2
                        radius 0.02
                      }
                    }
                    Solid {
                      translation 0 0 -0.11
                      children [
                        DEF sphere1 Shape {
                          appearance BrushedSteel {
                          }
                          geometry Sphere {
                            radius 0.02
                          }
                        }
                        Solid {
                          translation 0 -0.03 -9.99999e-08
                          rotation 1 0 0 1.5708
                          children [
                            DEF cylinder3 Shape {
                              appearance BrushedSteel {
                              }
                              geometry Cylinder {
                                height 0.06
                                radius 0.02
                              }
                            }
                            HingeJoint {
                              jointParameters HingeJointParameters {
                                position 386.7272329495048
                                axis 0 0 1
                                anchor -9.51224e-05 0.00113507 0.0800056
                              }
                              device [
                                RotationalMotor {
                                  name "wheel1_left"
                                }
                              ]
                              endPoint Solid {
                                translation -0.0015880959021684503 0.0019037479775544475 0.07994157767599397
                                rotation -5.7800419537177585e-06 -9.75704284328575e-07 -0.9999999999828196 2.818376668266083
                                children [
                                  DEF wheel Shape {
                                    appearance DamascusSteel {
                                    }
                                    geometry Cylinder {
                                      height 0.15
                                      radius 0.15
                                    }
                                  }
                                ]
                                boundingObject USE wheel
                                physics Physics {
                                  mass 1
                                }
                              }
                            }
                          ]
                          boundingObject USE cylinder3
                          physics DEF phy1 Physics {
                            mass 1
                          }
                        }
                      ]
                      name "solid(1)"
                      boundingObject USE sphere1
                      physics USE phy1
                    }
                  ]
                  boundingObject USE cylinder2
                  physics USE phy1
                }
              ]
              boundingObject USE sphere1
              physics USE phy1
            }
          ]
          boundingObject USE cylinder1
          physics USE phy1
        }
      ]
      name "wheel1_left_system"
      physics DEF phy1 Physics {
        mass 1
      }
    }
    Solid {
      translation 0.18 -0.24 0
      children [
        Solid {
          translation -0.0001757815149209252 -0.017333744024692788 0.0600545153188472
          rotation -0.9999999930027248 7.374603208071159e-05 -9.249904417794078e-05 1.5708786387286822
          children [
            DEF cylinder1 Shape {
              appearance DamascusSteel {
              }
              geometry Cylinder {
                height 0.09
                radius 0.02
              }
            }
            Solid {
              translation 0 0 -0.05
              children [
                DEF sphere1 Shape {
                  appearance BrushedSteel {
                  }
                  geometry Sphere {
                    radius 0.02
                  }
                }
                Solid {
                  translation 0 0.1 1.79608e-07
                  rotation -1 0 0 -1.5707953071795862
                  children [
                    DEF cylinder2 Shape {
                      appearance BrushedSteel {
                      }
                      geometry Cylinder {
                        height 0.2
                        radius 0.02
                      }
                    }
                    Solid {
                      translation 0 0 -0.11
                      children [
                        DEF sphere1 Shape {
                          appearance BrushedSteel {
                          }
                          geometry Sphere {
                            radius 0.02
                          }
                        }
                        Solid {
                          translation 0 -0.03 -9.99999e-08
                          rotation 1 0 0 1.5708
                          children [
                            DEF cylinder3 Shape {
                              appearance BrushedSteel {
                              }
                              geometry Cylinder {
                                height 0.06
                                radius 0.02
                              }
                            }
                            HingeJoint {
                              jointParameters HingeJointParameters {
                                position 80.05808705292723
                                axis 0 0 1
                                anchor 0.000341778 0.000558794 0.0800055
                              }
                              device [
                                RotationalMotor {
                                  name "wheel2_left"
                                }
                              ]
                              endPoint Solid {
                                translation -0.00027872775990710744 0.0009658852312778401 0.07993867002042876
                                rotation -1.5273215250973466e-06 1.5136313630369327e-06 -0.9999999999976881 1.6125677822048363
                                children [
                                  DEF wheel Shape {
                                    appearance DamascusSteel {
                                    }
                                    geometry Cylinder {
                                      height 0.15
                                      radius 0.15
                                    }
                                  }
                                ]
                                boundingObject USE wheel
                                physics Physics {
                                  mass 1
                                }
                              }
                            }
                          ]
                          boundingObject USE cylinder3
                          physics DEF phy1 Physics {
                            mass 1
                          }
                        }
                      ]
                      name "solid(1)"
                      boundingObject USE sphere1
                      physics USE phy1
                    }
                  ]
                  boundingObject USE cylinder2
                  physics USE phy1
                }
              ]
              boundingObject USE sphere1
              physics USE phy1
            }
          ]
          boundingObject USE cylinder1
          physics USE phy1
        }
      ]
      name "wheel2_left_system"
      physics USE phy1
    }
    Solid {
      translation -0.18 0.24 0
      children [
        Solid {
          translation -0.000177663 0.0173403 0.0599364
          rotation -0.9999999929357695 8.124469320562993e-05 -8.676267159571073e-05 1.5708626067521982
          children [
            DEF cylinder1 Shape {
              appearance DamascusSteel {
              }
              geometry Cylinder {
                height 0.09
                radius 0.02
              }
            }
            Solid {
              translation 0 0 0.05
              children [
                DEF sphere1 Shape {
                  appearance BrushedSteel {
                  }
                  geometry Sphere {
                    radius 0.02
                  }
                }
                Solid {
                  translation 0 0.1 1.79608e-07
                  rotation -1 0 0 -1.5707953071795862
                  children [
                    DEF cylinder2 Shape {
                      appearance BrushedSteel {
                      }
                      geometry Cylinder {
                        height 0.2
                        radius 0.02
                      }
                    }
                    Solid {
                      translation 0 0 -0.11
                      children [
                        DEF sphere1 Shape {
                          appearance BrushedSteel {
                          }
                          geometry Sphere {
                            radius 0.02
                          }
                        }
                        Solid {
                          translation 0 0.03 -9.99999e-08
                          rotation 1 0 0 1.5708
                          children [
                            DEF cylinder3 Shape {
                              appearance BrushedSteel {
                              }
                              geometry Cylinder {
                                height 0.06
                                radius 0.02
                              }
                            }
                            HingeJoint {
                              jointParameters HingeJointParameters {
                                position 401.3711520196712
                                axis 0 0 1
                                anchor 0.00237208 0.000614304 -0.0799754
                              }
                              device [
                                RotationalMotor {
                                  name "wheel1_right"
                                }
                              ]
                              endPoint Solid {
                                translation 0.0005927542725309839 0.0009623921258638419 -0.07999019576394151
                                rotation -0.38157012667764456 0.9243398933206419 -6.571965795861456e-06 3.141592480732279
                                children [
                                  DEF wheel Shape {
                                    appearance DamascusSteel {
                                    }
                                    geometry Cylinder {
                                      height 0.15
                                      radius 0.15
                                    }
                                  }
                                ]
                                boundingObject USE wheel
                                physics Physics {
                                  mass 1
                                }
                              }
                            }
                          ]
                          boundingObject USE cylinder3
                          physics DEF phy1 Physics {
                            mass 1
                          }
                        }
                      ]
                      name "solid(1)"
                      boundingObject USE sphere1
                      physics USE phy1
                    }
                  ]
                  boundingObject USE cylinder2
                  physics USE phy1
                }
              ]
              boundingObject USE sphere1
              physics USE phy1
            }
          ]
          boundingObject USE cylinder1
          physics USE phy1
        }
      ]
      name "wheel1_right_system"
      physics DEF phy1 Physics {
        mass 1
      }
    }
    Solid {
      translation 0.18 0.24 0
      children [
        Solid {
          translation -0.000177663 0.0173403 0.0599364
          rotation -0.9999999929357695 8.124469320562993e-05 -8.676267159571073e-05 1.5708626067521982
          children [
            DEF cylinder1 Shape {
              appearance DamascusSteel {
              }
              geometry Cylinder {
                height 0.09
                radius 0.02
              }
            }
            Solid {
              translation 0 0 0.05
              children [
                DEF sphere1 Shape {
                  appearance BrushedSteel {
                  }
                  geometry Sphere {
                    radius 0.02
                  }
                }
                Solid {
                  translation 0 0.1 1.79608e-07
                  rotation -1 0 0 -1.5707953071795862
                  children [
                    DEF cylinder2 Shape {
                      appearance BrushedSteel {
                      }
                      geometry Cylinder {
                        height 0.2
                        radius 0.02
                      }
                    }
                    Solid {
                      translation 0 0 -0.11
                      children [
                        DEF sphere1 Shape {
                          appearance BrushedSteel {
                          }
                          geometry Sphere {
                            radius 0.02
                          }
                        }
                        Solid {
                          translation 0 0.03 -9.99999e-08
                          rotation 1 0 0 1.5708
                          children [
                            DEF cylinder3 Shape {
                              appearance BrushedSteel {
                              }
                              geometry Cylinder {
                                height 0.06
                                radius 0.02
                              }
                            }
                            HingeJoint {
                              jointParameters HingeJointParameters {
                                position 402.92913248966374
                                axis 0 0 1
                                anchor 0.00237208 0.000614304 -0.0799754
                              }
                              device [
                                RotationalMotor {
                                  name "wheel2_right"
                                }
                              ]
                              endPoint Solid {
                                translation 0.001778647113596999 -0.00094893869160658 -0.07998820342901869
                                rotation 0.9209396584084534 -0.38970520340047765 3.6212778303321426e-06 3.1416012352712586
                                children [
                                  DEF wheel Shape {
                                    appearance DamascusSteel {
                                    }
                                    geometry Cylinder {
                                      height 0.15
                                      radius 0.15
                                    }
                                  }
                                ]
                                boundingObject USE wheel
                                physics Physics {
                                  mass 1
                                }
                              }
                            }
                          ]
                          boundingObject USE cylinder3
                          physics DEF phy1 Physics {
                            mass 1
                          }
                        }
                      ]
                      name "solid(1)"
                      boundingObject USE sphere1
                      physics USE phy1
                    }
                  ]
                  boundingObject USE cylinder2
                  physics USE phy1
                }
              ]
              boundingObject USE sphere1
              physics USE phy1
            }
          ]
          boundingObject USE cylinder1
          physics USE phy1
        }
      ]
      name "wheel2_right_system"
      physics DEF phy1 Physics {
        mass 1
      }
    }
    Solid {
      translation -0.3 0 0.4
      children [
        DEF camStand Shape {
          appearance Copper {
          }
          geometry Cylinder {
            height 0.6
            radius 0.02
          }
        }
        SliderJoint {
          jointParameters JointParameters {
            position 0.26995124886558547
            minStop -0.3
            maxStop 0.3
            dampingConstant 1
            staticFriction 3
          }
          device [
            LinearMotor {
              name "cam_slider"
            }
          ]
          endPoint Solid {
            translation -2.9551326349519513e-05 -1.991890490060655e-05 0.2699430562633293
            rotation -3.0884260299697183e-06 -2.9264584594029586e-07 0.9999999999951881 -3.141585063926957
            children [
              DEF box1 Shape {
                appearance RoughPolymer {
                }
                geometry Box {
                  size 0.05 0.05 0.05
                }
              }
              Camera {
              }
            ]
            boundingObject USE box1
            physics USE phy1
          }
        }
      ]
      name "camStand"
      boundingObject USE camStand
      physics USE phy1
    }
  ]
  boundingObject USE body
  physics DEF phy Physics {
    mass 1
  }
  controller "robo_controller"
}
Solid {
  translation -16.983718710614948 -17.94553817461199 -1.3277441326283799
  rotation 0.35623241429773667 0.6892703703172062 0.6308762347769863 2.5450695867116884
  children [
    DEF box Shape {
      appearance DryMud {
      }
      geometry Box {
        size 2.5 2 0.4
      }
    }
  ]
  boundingObject USE box
  physics USE phy1
}
